在Go语言中，可以在一个goroutine中触发`panic`并使用`recover`进行恢复。每个goroutine都有自己的调用栈，因此在一个goroutine中的`panic`只能在同一个goroutine中通过`recover`来捕获和处理。

以下是一个例子，展示了如何在goroutine中触发`panic`并使用`recover`进行恢复：

```go
package main

import (
    "fmt"
    "time"
)

func main() {
    go func() {
        // 捕获并恢复panic
        defer func() {
            if r := recover(); r != nil {
                fmt.Println("Recovered in goroutine:", r)
            }
        }()

        fmt.Println("Goroutine is about to panic...")
        panic("Panic in goroutine") // 触发panic
        fmt.Println("This line will not be executed.") // 这行代码不会被执行
    }()

    // 等待goroutine执行完毕
    time.Sleep(1 * time.Second)
    fmt.Println("Main function continues to execute.")
}
```

在这个例子中，一个goroutine在启动后触发了`panic`，但在goroutine内部使用`defer`和`recover`机制捕获并处理了这个`panic`。主程序等待一秒钟，确保goroutine有足够的时间执行，然后继续执行。

输出结果如下：

```
Goroutine is about to panic...
Recovered in goroutine: Panic in goroutine
Main function continues to execute.
```

可以看到，`panic`在goroutine中被成功捕获和恢复，主程序继续执行。

如果不使用`recover`，`panic`会导致整个程序崩溃，即使是在goroutine中。以下是一个不使用`recover`的例子：

```go
package main

import (
    "fmt"
    "time"
)

func main() {
    go func() {
        fmt.Println("Goroutine is about to panic...")
        panic("Panic in goroutine") // 触发panic
        fmt.Println("This line will not be executed.") // 这行代码不会被执行
    }()

    // 等待goroutine执行完毕
    time.Sleep(1 * time.Second)
    fmt.Println("Main function continues to execute.")
}
```

输出结果如下：

```
Goroutine is about to panic...
panic: Panic in goroutine

goroutine 5 [running]:
main.main.func1()
        /path/to/your/code/main.go:12 +0x39
created by main.main
        /path/to/your/code/main.go:10 +0x25
exit status 2
```

在这个例子中，`panic`在goroutine中没有被捕获和恢复，导致整个程序崩溃并退出。