在Go语言中，`panic`并不属于普通的错误类型（如实现了`error`接口的类型），而是一个特殊的运行时错误处理机制。`panic`用于表示程序遇到无法恢复的错误，程序在调用`panic`后会中止执行，并开始向上传播，逐层退出调用栈中的函数，直到遇到`recover`函数或者程序终止。

以下是一个简单的例子，展示了如何使用`panic`以及如何通过`recover`来捕获并处理`panic`：

```go
package main

import (
    "fmt"
)

func main() {
    // 延迟执行的匿名函数，用于捕获panic
    defer func() {
        if r := recover(); r != nil {
            fmt.Println("Recovered from panic:", r)
        }
    }()

    fmt.Println("Starting the program...")
    causePanic()
    fmt.Println("This line will not be executed.") // 这行代码不会被执行，因为程序在调用panic后会中止执行
}

func causePanic() {
    fmt.Println("About to panic...")
    panic("Something went wrong!") // 触发panic
    fmt.Println("This line will not be executed.") // 这行代码不会被执行
}
```

在这个例子中，`causePanic`函数触发了`panic`，但由于在`main`函数中使用了`defer`和`recover`机制，程序并不会直接崩溃，而是捕获了`panic`并打印出错误信息，然后继续执行`main`函数中的后续代码（如果有的话）。

输出结果如下：

```
Starting the program...
About to panic...
Recovered from panic: Something went wrong!
```

这个例子说明了`panic`用于处理严重错误的情况，而不是用于普通的错误处理。如果错误可以通过逻辑处理解决，应该使用返回错误值的方式而不是`panic`。