在Go语言中，如果在`recover`后再次触发`panic`，程序会重新进入`panic`状态并开始新的传播过程，直至遇到新的`recover`或者程序终止。

以下是一个例子，展示了在`recover`后再次触发`panic`的情况：

```go
package main

import (
    "fmt"
)

func main() {
    // 第一层捕获panic
    defer func() {
        if r := recover(); r != nil {
            fmt.Println("Recovered in main from:", r)
            // 在recover后再次触发panic
            panic("New panic after recovery")
        }
    }()

    fmt.Println("Starting the program...")
    causePanic()
    fmt.Println("This line will not be executed.") // 这行代码不会被执行，因为程序在调用panic后会中止执行
}

func causePanic() {
    fmt.Println("About to panic...")
    panic("Original panic")
    fmt.Println("This line will not be executed.") // 这行代码不会被执行
}
```

在这个例子中，`causePanic`函数首先触发了`panic`，然后`main`函数中的`defer`函数通过`recover`捕获了这个`panic`。在`recover`之后，`defer`函数再次触发了一个新的`panic`。

输出结果如下：

```
Starting the program...
About to panic...
Recovered in main from: Original panic
panic: New panic after recovery

goroutine 1 [running]:
main.main.func1()
        /path/to/your/code/main.go:11 +0x85
main.main()
        /path/to/your/code/main.go:17 +0x13b
```

在这个例子中，`recover`成功捕获了第一次`panic`，但在`recover`之后再次触发了新的`panic`，这会导致程序最终中止并打印出新的`panic`信息。

如果在新的`panic`传播过程中再次遇到`recover`，则可以再次捕获这个新的`panic`。例如：

```go
package main

import (
    "fmt"
)

func main() {
    // 第一层捕获panic
    defer func() {
        if r := recover(); r != nil {
            fmt.Println("Recovered in main from:", r)
            // 在recover后再次触发panic
            panic("New panic after recovery")
        }
    }()

    // 第二层捕获panic
    defer func() {
        if r := recover(); r != nil {
            fmt.Println("Recovered in second defer from:", r)
        }
    }()

    fmt.Println("Starting the program...")
    causePanic()
    fmt.Println("This line will not be executed.") // 这行代码不会被执行，因为程序在调用panic后会中止执行
}

func causePanic() {
    fmt.Println("About to panic...")
    panic("Original panic")
    fmt.Println("This line will not be executed.") // 这行代码不会被执行
}
```

输出结果如下：

```
Starting the program...
About to panic...
Recovered in main from: Original panic
Recovered in second defer from: New panic after recovery
```

在这个例子中，第二层的`defer`函数成功捕获了新的`panic`，程序继续执行。