当然，下面是一个使用 `new Promise` 创建 Promise 对象，并处理正常（成功）和异常（失败）情况的示例。

### 示例说明

我们将创建一个模拟异步操作的 Promise，比如一个简单的“任务”函数，该函数在一定条件下会成功或失败。然后，我们将使用 `.then()` 来处理成功的情况，使用 `.catch()` 来处理异常情况。

### 代码示例

```javascript
// 创建一个返回 Promise 的函数
function performTask(isSuccess) {
  return new Promise((resolve, reject) => {
    // 模拟异步操作，例如网络请求或文件读写
    setTimeout(() => {
      if (isSuccess) {
        resolve('任务成功完成！');
      } else {
        reject(new Error('任务失败了。'));
      }
    }, 1000); // 延迟1秒
  });
}

// 调用 performTask 并处理结果
performTask(true) // 传入 true 表示任务成功
  .then((message) => {
    console.log('成功:', message);
  })
  .catch((error) => {
    console.error('错误:', error.message);
  });

// 调用 performTask 并处理失败情况
performTask(false) // 传入 false 表示任务失败
  .then((message) => {
    console.log('成功:', message);
  })
  .catch((error) => {
    console.error('错误:', error.message);
  });
```

### 代码解析

1. **创建 Promise 对象**
   ```javascript
   new Promise((resolve, reject) => {
     // 异步操作
   });
   ```
   - `resolve` 用于在异步操作成功时调用，并传递成功的结果。
   - `reject` 用于在异步操作失败时调用，并传递错误信息。

2. **模拟异步操作**
   ```javascript
   setTimeout(() => {
     if (isSuccess) {
       resolve('任务成功完成！');
     } else {
       reject(new Error('任务失败了。'));
     }
   }, 1000);
   ```
   - 使用 `setTimeout` 模拟一个耗时1秒的异步操作。
   - 根据传入的 `isSuccess` 参数决定是调用 `resolve` 还是 `reject`。

3. **处理 Promise 结果**
   ```javascript
   performTask(true)
     .then((message) => {
       console.log('成功:', message);
     })
     .catch((error) => {
       console.error('错误:', error.message);
     });
   ```
   - 当 `performTask(true)` 被调用时，Promise 会在1秒后被 `resolve`，触发 `.then()` 中的回调，输出成功信息。
   - 当 `performTask(false)` 被调用时，Promise 会在1秒后被 `reject`，触发 `.catch()` 中的回调，输出错误信息。

### 控制台输出

运行上述代码后，控制台将依次输出：

```
成功: 任务成功完成！
错误: 任务失败了。
```

### 进一步优化：使用 `async/await`

为了让异步代码更加简洁，可以使用 `async/await` 语法来处理 Promise。

```javascript
async function executeTask() {
  try {
    const successMessage = await performTask(true);
    console.log('成功:', successMessage);
  } catch (error) {
    console.error('错误:', error.message);
  }

  try {
    const failureMessage = await performTask(false);
    console.log('成功:', failureMessage);
  } catch (error) {
    console.error('错误:', error.message);
  }
}

executeTask();
```

### 使用 `async/await` 的优势

- 代码更具可读性，类似于同步代码的结构。
- 错误处理更加直观，通过 `try...catch` 语句捕获异常。

运行上述 `executeTask` 函数，同样会在控制台输出：

```
成功: 任务成功完成！
错误: 任务失败了。
```

通过以上示例，你可以了解到如何使用 `new Promise` 创建 Promise 对象，并通过 `.then()/.catch()` 或 `async/await` 来处理成功和失败的情况。